<?xml version="1.0" ?>
<robot name="zau2" version="1.0">
  <material name="Yellow">
    <color rgba="1.0 1.0 0.0 1.0"/>
  </material>
  <material name="Orange">
    <color rgba="1.0 0.4 0.0 1.0"/>
  </material>
  <material name="grey">
    <color rgba="0.7 0.7 0.7 1.0"/>
  </material>
  <material name="Pink">
    <color rgba="1.0 0.0 0.8 1.0"/>
  </material>
  <material name="dark">
    <color rgba="0.3 0.3 0.3 1.0"/>
  </material>
  <material name="light_black">
    <color rgba="0.4 0.4 0.4 1.0"/>
  </material>
  <gazebo reference="base_link_mb">
    <sensor name="base_link_mb" type="contact">
      <update_rate>1000.0</update_rate>
      <always_on>true</always_on>
      <contact>
        <collision>base_footprint_fixed_joint_lump__base_link_collision</collision>
      </contact>
      <plugin filename="libgazebo_ros_bumper.so" name="base_link_contact_sensor_plugin">
        <bumperTopicName>contact</bumperTopicName>
        <frameName>world</frameName>
      </plugin>
    </sensor>
  </gazebo>
  <gazebo reference="base_link_mb">
    <material>Gazebo/DarkGrey</material>
  </gazebo>
  <gazebo reference="wheel_left_link">
    <mu1 value="1.0"/>
    <mu2 value="1.0"/>
    <kp value="10000000.0"/>
    <kd value="1.0"/>
    <minDepth>0.001</minDepth>
    <maxVel>0.1</maxVel>
    <fdir1>1 0 0</fdir1>
    <material>Gazebo/FlatBlack</material>
  </gazebo>
  <gazebo reference="wheel_right_link">
    <mu1 value="1.0"/>
    <mu2 value="1.0"/>
    <kp value="10000000.0"/>
    <kd value="1.0"/>
    <minDepth>0.001</minDepth>
    <maxVel>0.1</maxVel>
    <fdir1>1 0 0</fdir1>
    <material>Gazebo/FlatBlack</material>
  </gazebo>
  <gazebo reference="caster_back_right_link">
    <mu1>0.1</mu1>
    <mu2>0.1</mu2>
    <kp>1000000.0</kp>
    <kd>100.0</kd>
    <minDepth>0.001</minDepth>
    <maxVel>1.0</maxVel>
    <material>Gazebo/FlatBlack</material>
  </gazebo>
  <gazebo reference="caster_back_left_link">
    <mu1>0.1</mu1>
    <mu2>0.1</mu2>
    <kp>1000000.0</kp>
    <kd>100.0</kd>
    <minDepth>0.001</minDepth>
    <maxVel>1.0</maxVel>
    <material>Gazebo/FlatBlack</material>
  </gazebo>
  <gazebo reference="caster_front_right_link">
    <mu1>0.1</mu1>
    <mu2>0.1</mu2>
    <kp>1000000.0</kp>
    <kd>100.0</kd>
    <minDepth>0.001</minDepth>
    <maxVel>1.0</maxVel>
    <material>Gazebo/FlatBlack</material>
  </gazebo>
  <gazebo reference="caster_front_left_link">
    <mu1>0.1</mu1>
    <mu2>0.1</mu2>
    <kp>1000000.0</kp>
    <kd>100.0</kd>
    <minDepth>0.001</minDepth>
    <maxVel>1.0</maxVel>
    <material>Gazebo/FlatBlack</material>
  </gazebo>
  <gazebo reference="imu_link">
    <sensor name="imu" type="imu">
      <always_on>true</always_on>
      <visualize>false</visualize>
    </sensor>
    <material>Gazebo/Grey</material>
  </gazebo>
  <gazebo>
    <plugin filename="libgazebo_ros_diff_drive.so" name="moving_base_controller">
      <commandTopic>cmd_vel</commandTopic>
      <odometryTopic>odom</odometryTopic>
      <odometryFrame>odom</odometryFrame>
      <odometrySource>world</odometrySource>
      <publishOdomTF>true</publishOdomTF>
      <robotBaseFrame>base_footprint</robotBaseFrame>
      <publishWheelTF>false</publishWheelTF>
      <publishTf>true</publishTf>
      <publishWheelJointState>true</publishWheelJointState>
      <legacyMode>false</legacyMode>
      <updateRate>30</updateRate>
      <leftJoint>wheel_left_joint</leftJoint>
      <rightJoint>wheel_right_joint</rightJoint>
      <wheelSeparation>0.650</wheelSeparation>
      <wheelDiameter>0.168</wheelDiameter>
      <wheelAcceleration>1</wheelAcceleration>
      <wheelTorque>50</wheelTorque>
      <rosDebugLevel>na</rosDebugLevel>
    </plugin>
  </gazebo>
  <gazebo>
    <plugin filename="libgazebo_ros_imu.so" name="imu_plugin">
      <alwaysOn>true</alwaysOn>
      <bodyName>imu_link</bodyName>
      <frameName>imu_link</frameName>
      <topicName>imu</topicName>
      <serviceName>imu_service</serviceName>
      <gaussianNoise>0.0</gaussianNoise>
      <updateRate>0</updateRate>
      <imu>
        <noise>
          <type>gaussian</type>
          <rate>
            <mean>0.0</mean>
            <stddev>2e-4</stddev>
            <bias_mean>0.0000075</bias_mean>
            <bias_stddev>0.0000008</bias_stddev>
          </rate>
          <accel>
            <mean>0.0</mean>
            <stddev>1.7e-2</stddev>
            <bias_mean>0.1</bias_mean>
            <bias_stddev>0.001</bias_stddev>
          </accel>
        </noise>
      </imu>
    </plugin>
  </gazebo>
  <gazebo reference="base_scan_front">
    <material>Gazebo/DarkGrey</material>
    <sensor name="lds_lfcd_sensor_front" type="ray">
      <pose>0 0 0 0 0 0</pose>
      <visualize>true</visualize>
      <update_rate>5</update_rate>
      <ray>
        <scan>
          <horizontal>
            <samples>360</samples>
            <resolution>1</resolution>
            <min_angle>0</min_angle>
            <max_angle>4.71</max_angle>
          </horizontal>
        </scan>
        <range>
          <min>0.120</min>
          <max>3.5</max>
          <resolution>0.015</resolution>
        </range>
        <noise>
          <type>gaussian</type>
          <mean>0.0</mean>
          <stddev>0.01</stddev>
        </noise>
      </ray>
      <plugin filename="libgazebo_ros_laser.so" name="gazebo_ros_lds_lfcd_controller">
        <topicName>laser/scan_front</topicName>
        <frameName>base_scan_front</frameName>
      </plugin>
    </sensor>
  </gazebo>
  <gazebo reference="base_scan_back">
    <material>Gazebo/DarkGrey</material>
    <sensor name="lds_lfcd_sensor_back" type="ray">
      <pose>0 0 0 0 0 0</pose>
      <visualize>true</visualize>
      <update_rate>5</update_rate>
      <ray>
        <scan>
          <horizontal>
            <samples>360</samples>
            <resolution>1</resolution>
            <min_angle>0</min_angle>
            <max_angle>4.71</max_angle>
          </horizontal>
        </scan>
        <range>
          <min>0.120</min>
          <max>3.5</max>
          <resolution>0.015</resolution>
        </range>
        <noise>
          <type>gaussian</type>
          <mean>0.0</mean>
          <stddev>0.01</stddev>
        </noise>
      </ray>
      <plugin filename="libgazebo_ros_laser.so" name="gazebo_ros_lds_lfcd_controller">
        <topicName>laser/scan_back</topicName>
        <frameName>base_scan_back</frameName>
      </plugin>
    </sensor>
  </gazebo>
  <joint name="velodyne_base_mount_joint" type="fixed">
    <origin xyz="-0.35 0.05 0.85" rpy="0.0 0.0 0.0"/>
    <parent link="base_link_mb"/>
    <child link="velodyne_base_link"/>
  </joint>
  <link name="velodyne_base_link">
    <inertial>
      <origin xyz="0.0 0.0 0.03585" rpy="0 0 0"/>
      <mass value="0.83"/>
      <inertia ixx="0.000908059425" ixy="0.0" ixz="0.0" iyy="0.000908059425" iyz="0.0" izz="0.0011049624"/>
    </inertial>
    <visual>
      <geometry>
        <mesh filename="package://velodyne_description/meshes/VLP16_base_1.dae"/>
      </geometry>
    </visual>
    <visual>
      <geometry>
        <mesh filename="package://velodyne_description/meshes/VLP16_base_2.dae"/>
      </geometry>
    </visual>
    <collision>
      <origin xyz="0.0 0.0 0.03585" rpy="0.0 0.0 0.0"/>
      <geometry>
        <cylinder radius="0.0516" length="0.0717"/>
      </geometry>
    </collision>
  </link>
  <joint name="velodyne_base_scan_joint" type="fixed">
    <origin xyz="0.0 0.0 0.0377" rpy="0.0 0.0 0.0"/>
    <parent link="velodyne_base_link"/>
    <child link="velodyne"/>
  </joint>
  <link name="velodyne">
    <inertial>
      <origin xyz="0.0 0.0 0.0" rpy="0 0 0"/>
      <mass value="0.01"/>
      <inertia ixx="1e-07" ixy="0.0" ixz="0.0" iyy="1e-07" iyz="0.0" izz="1e-07"/>
    </inertial>
    <visual>
      <origin xyz="0.0 0.0 -0.0377" rpy="0 0 0"/>
      <geometry>
        <mesh filename="package://velodyne_description/meshes/VLP16_scan.dae"/>
      </geometry>
    </visual>
    <collision>
      <geometry>
        <sphere radius="0.0"/>
      </geometry>
    </collision>
  </link>
  <gazebo reference="velodyne">
    <sensor name="velodyne-VLP16" type="ray">
      <pose>0 0 0 0 0 0</pose>
      <visualize>false</visualize>
      <update_rate>10</update_rate>
      <ray>
        <scan>
          <horizontal>
            <samples>440</samples>
            <resolution>1</resolution>
            <min_angle>-3.141592653589793</min_angle>
            <max_angle>3.141592653589793</max_angle>
          </horizontal>
          <vertical>
            <samples>16</samples>
            <resolution>1</resolution>
            <min_angle>-0.2617993877991494</min_angle>
            <max_angle> 0.2617993877991494</max_angle>
          </vertical>
        </scan>
        <range>
          <min>0.3</min>
          <max>131.0</max>
          <resolution>0.001</resolution>
        </range>
        <noise>
          <type>gaussian</type>
          <mean>0.0</mean>
          <stddev>0.0</stddev>
        </noise>
      </ray>
      <plugin filename="libgazebo_ros_velodyne_laser.so" name="gazebo_ros_laser_controller">
        <topicName>/velodyne_points</topicName>
        <frameName>velodyne</frameName>
        <organize_cloud>False</organize_cloud>
        <min_range>0.9</min_range>
        <max_range>130.0</max_range>
        <gaussianNoise>0.008</gaussianNoise>
      </plugin>
    </sensor>
  </gazebo>
  <joint name="camera_mb_joint" type="fixed">
    <origin xyz="-0.35 0.18 0.87" rpy="0.0 0.0 3.14"/>
    <parent link="base_link_mb"/>
    <child link="camera_mb_link"/>
  </joint>
  <link name="camera_mb_link">
    <inertial>
      <origin xyz="0.0 0.0 0.0" rpy="0 0 0"/>
      <mass value="0.564"/>
      <inertia ixx="0.003881243" ixy="0.0" ixz="0.0" iyy="0.00049894" iyz="0.0" izz="0.003879257"/>
    </inertial>
    <collision>
      <origin xyz="-0.01 -0.06 0.0" rpy="0.0 0.0 0.0"/>
      <geometry>
        <box size="0.04 0.165 0.03"/>
      </geometry>
    </collision>
  </link>
  <gazebo reference="camera_mb_link">
    <selfCollide>false</selfCollide>
  </gazebo>
  <joint name="camera_mb_rgb_joint" type="fixed">
    <origin xyz="-0.0018095100238921474 -0.03272426083777126 -0.0005945277060679762" rpy="-0.0027991448367402274 0.003519755156089867 0.005505550116665536"/>
    <parent link="camera_mb_link"/>
    <child link="camera_mb_rgb_frame"/>
  </joint>
  <link name="camera_mb_rgb_frame"/>
  <joint name="camera_mb_rgb_optical_joint" type="fixed">
    <origin xyz="0.0 0.0 0.0" rpy="-1.5707963267948966 0.0 -1.5707963267948966"/>
    <parent link="camera_mb_rgb_frame"/>
    <child link="camera_mb_rgb_optical_frame"/>
  </joint>
  <link name="camera_mb_rgb_optical_frame">
    <visual>
      <origin xyz="0.0 0.0 -0.03" rpy="1.5707963267948966 0.0 0.0"/>
      <geometry>
        <mesh filename="package://zau2_description/meshes/sensors/astra2.dae" scale="1.0 1.0 1.0"/>
      </geometry>
    </visual>
  </link>
  <joint name="camera_mb_depth_joint" type="fixed">
    <origin xyz="0.0 -0.02 0.0" rpy="0.0 0.0 0.0"/>
    <parent link="camera_mb_link"/>
    <child link="camera_mb_depth_frame"/>
  </joint>
  <link name="camera_mb_depth_frame"/>
  <joint name="camera_mb_depth_optical_joint" type="fixed">
    <origin xyz="0.0 0.0 0.0" rpy="-1.5707963267948966 0.0 -1.5707963267948966"/>
    <parent link="camera_mb_depth_frame"/>
    <child link="camera_mb_depth_optical_frame"/>
  </joint>
  <link name="camera_mb_depth_optical_frame"/>
  <gazebo reference="camera_mb_depth_frame">
    <sensor name="camera" type="depth">
      <always_on>true</always_on>
      <update_rate>20.0</update_rate>
      <camera>
        <horizontal_fov>1.0471975511965976</horizontal_fov>
        <image>
          <format>B8G8R8</format>
          <width>640</width>
          <height>480</height>
        </image>
        <clip>
          <near>0.10</near>
          <far>8.0</far>
        </clip>
      </camera>
      <plugin filename="libgazebo_ros_openni_kinect.so" name="camera_mb_camera_controller">
        <cameraName>camera_mb</cameraName>
        <alwaysOn>true</alwaysOn>
        <updateRate>10</updateRate>
        <imageTopicName>rgb/image_raw</imageTopicName>
        <depthImageTopicName>depth/image_raw</depthImageTopicName>
        <pointCloudTopicName>depth/points</pointCloudTopicName>
        <cameraInfoTopicName>rgb/camera_info</cameraInfoTopicName>
        <depthImageCameraInfoTopicName>depth/camera_info</depthImageCameraInfoTopicName>
        <frameName>camera_mb_depth_optical_frame</frameName>
        <baseline>0.1</baseline>
        <distortion_k1>0.0</distortion_k1>
        <distortion_k2>0.0</distortion_k2>
        <distortion_k3>0.0</distortion_k3>
        <distortion_t1>0.0</distortion_t1>
        <distortion_t2>0.0</distortion_t2>
        <pointCloudCutoff>0.4</pointCloudCutoff>
      </plugin>
    </sensor>
  </gazebo>
  <material name="white">
    <color rgba="1.0 1.0 1.0 1.0"/>
  </material>
  <link name="camera_realsense_realsense_mountpoint"/>
  <joint name="camera_realsense_realsense_mountpoint_joint" type="fixed">
    <origin xyz="0.35 -0.18 0.85" rpy="0.0 0.0 0.0"/>
    <parent link="base_link_mb"/>
    <child link="camera_realsense_realsense_mountpoint"/>
  </joint>
  <link name="camera_realsense_realsense_lens">
    <visual>
      <origin xyz="0.0115 0.0 0.01" rpy="1.570796 0.0 1.570796"/>
      <geometry>
        <mesh filename="package://realsense2_description/meshes/d415.stl"/>
      </geometry>
      <material name="white"/>
    </visual>
  </link>
  <joint name="camera_realsense_realsense_lens_joint" type="fixed">
    <origin xyz="0.0 0.0 0.0" rpy="0.0 0.0 0.0"/>
    <parent link="camera_realsense_realsense_mountpoint"/>
    <child link="camera_realsense_realsense_lens"/>
  </joint>
  <joint name="camera_realsense_realsense_joint" type="fixed">
    <origin xyz="0.025 0.0 0.0" rpy="0.0 0.0 0.0"/>
    <parent link="camera_realsense_realsense_lens"/>
    <child link="camera_realsense_realsense"/>
  </joint>
  <link name="camera_realsense_realsense"/>
  <link name="camera_realsense_realsense_gazebo"/>
  <joint name="camera_realsense_realsense_gazebo_joint" type="fixed">
    <origin xyz="0.0 0.0 0.0" rpy="-1.5707963267948966 0.0 -1.5707963267948966"/>
    <parent link="camera_realsense_realsense"/>
    <child link="camera_realsense_realsense_gazebo"/>
  </joint>
  <gazebo reference="camera_realsense_realsense">
    <turnGravityOff>true</turnGravityOff>
    <sensor name="camera_realsense_realsense_depth" type="depth">
      <update_rate>30</update_rate>
      <camera>
        <horizontal_fov>1.5184351666666667</horizontal_fov>
        <vertical_fov>1.0122901111111111</vertical_fov>
        <image>
          <width>640</width>
          <height>480</height>
          <format>RGB_INT8</format>
        </image>
        <clip>
          <near>0.01</near>
          <far>50.0</far>
        </clip>
      </camera>
      <plugin filename="libgazebo_ros_openni_kinect.so" name="kinect_controller">
        <baseline>0.2</baseline>
        <alwaysOn>true</alwaysOn>
        <updateRate>30</updateRate>
        <cameraName>realsense</cameraName>
        <imageTopicName>color/image_raw</imageTopicName>
        <cameraInfoTopicName>color/camera_info</cameraInfoTopicName>
        <depthImageTopicName>depth/image_rect_raw</depthImageTopicName>
        <depthImageInfoTopicName>depth/camera_info</depthImageInfoTopicName>
        <pointCloudTopicName>depth/color/points</pointCloudTopicName>
        <frameName>camera_realsense_realsense_gazebo</frameName>
        <pointCloudCutoff>0.105</pointCloudCutoff>
        <pointCloudCutoffMax>8.0</pointCloudCutoffMax>
        <distortionK1>0.00000001</distortionK1>
        <distortionK2>0.00000001</distortionK2>
        <distortionK3>0.00000001</distortionK3>
        <distortionT1>0.00000001</distortionT1>
        <distortionT2>0.00000001</distortionT2>
        <CxPrime>0</CxPrime>
        <Cx>0</Cx>
        <Cy>0</Cy>
        <focalLength>0</focalLength>
        <hackBaseline>0</hackBaseline>
      </plugin>
    </sensor>
  </gazebo>
  <material name="aluminum">
    <color rgba="0.5 0.5 0.5 1.0"/>
  </material>
  <material name="plastic">
    <color rgba="0.1 0.1 0.1 1.0"/>
  </material>
  <joint name="camera_l515_joint" type="fixed">
    <origin xyz="0.35 0.18 0.85" rpy="0.0 0.0 0.0"/>
    <parent link="base_link_mb"/>
    <child link="camera_l515_bottom_screw_frame"/>
  </joint>
  <link name="camera_l515_bottom_screw_frame"/>
  <joint name="camera_l515_link_joint" type="fixed">
    <origin xyz="0.007500000000000001 0.0 0.021150000000000002" rpy="0.0 0.0 0.0"/>
    <parent link="camera_l515_bottom_screw_frame"/>
    <child link="camera_l515_link"/>
  </joint>
  <link name="camera_l515_link">
    <inertial>
      <origin xyz="0.0 0.0 0.0" rpy="0 0 0"/>
      <mass value="0.095"/>
      <inertia ixx="4.4e-05" ixy="0.0" ixz="0.0" iyy="2.7e-05" iyz="0.0" izz="2.7e-05"/>
    </inertial>
    <visual>
      <origin xyz="0.0045 0.0 0.009000000000000001" rpy="1.5707963267948966 0.0 1.5707963267948966"/>
      <geometry>
        <mesh filename="package://realsense2_description/meshes/l515.dae"/>
      </geometry>
    </visual>
    <collision>
      <origin xyz="-0.0085 0.0 0.009000000000000001" rpy="1.5707963267948966 0.0 1.5707963267948966"/>
      <geometry>
        <cylinder radius="0.0305" length="0.026"/>
      </geometry>
    </collision>
  </link>
  <joint name="camera_l515_lower_mount_joint" type="fixed">
    <origin xyz="-0.013999999999999999 0.0 0.01015" rpy="0.0 0.0 0.0"/>
    <parent link="camera_l515_bottom_screw_frame"/>
    <child link="camera_l515_lower_mount"/>
  </joint>
  <link name="camera_l515_lower_mount"/>
  <joint name="camera_l515_upper_mount_joint" type="fixed">
    <origin xyz="-0.013999999999999999 0.0 0.05015" rpy="0.0 0.0 0.0"/>
    <parent link="camera_l515_bottom_screw_frame"/>
    <child link="camera_l515_upper_mount"/>
  </joint>
  <link name="camera_l515_upper_mount"/>
  <gazebo reference="camera_l515_link">
    <self_collide>0</self_collide>
    <enable_wind>0</enable_wind>
    <kinematic>0</kinematic>
    <gravity>1</gravity>
    <mu2>1</mu2>
    <fdir1>0 0 0</fdir1>
    <kp>1e+13</kp>
    <kd>1</kd>
    <sensor name="camera_l515color" type="camera">
      <camera name="camera_l515">
        <horizontal_fov>1.2393583018411736</horizontal_fov>
        <image>
          <width>1920</width>
          <height>1080</height>
          <format>RGB_INT8</format>
        </image>
        <clip>
          <near>0.1</near>
          <far>100</far>
        </clip>
        <noise>
          <type>gaussian</type>
          <mean>0.0</mean>
          <stddev>0.007</stddev>
        </noise>
      </camera>
      <always_on>1</always_on>
      <update_rate>30</update_rate>
      <visualize>1</visualize>
    </sensor>
    <sensor name="camera_l515ired" type="camera">
      <camera name="camera_l515">
        <horizontal_fov>1.2217304763960306</horizontal_fov>
        <image>
          <width>1024</width>
          <height>768</height>
          <format>L_INT8</format>
        </image>
        <clip>
          <near>0.1</near>
          <far>100</far>
        </clip>
        <noise>
          <type>gaussian</type>
          <mean>0.0</mean>
          <stddev>0.05</stddev>
        </noise>
      </camera>
      <always_on>1</always_on>
      <update_rate>90</update_rate>
      <visualize>0</visualize>
    </sensor>
    <sensor name="camera_l515depth" type="depth">
      <camera name="camera_l515">
        <horizontal_fov>1.2217304763960306</horizontal_fov>
        <image>
          <width>1024</width>
          <height>768</height>
        </image>
        <clip>
          <near>0.1</near>
          <far>100</far>
        </clip>
        <noise>
          <type>gaussian</type>
          <mean>0.0</mean>
          <stddev>0.100</stddev>
        </noise>
      </camera>
      <always_on>1</always_on>
      <update_rate>90</update_rate>
      <visualize>0</visualize>
    </sensor>
  </gazebo>
  <gazebo>
    <plugin filename="librealsense_gazebo_plugin.so" name="camera_l515">
      <prefix>camera_l515</prefix>
      <depthUpdateRate>30.0</depthUpdateRate>
      <colorUpdateRate>30.0</colorUpdateRate>
      <infraredUpdateRate>30.0</infraredUpdateRate>
      <depthTopicName>/camera_l515/depth/image_rect_raw</depthTopicName>
      <depthCameraInfoTopicName>/camera_l515/depth/camera_info</depthCameraInfoTopicName>
      <colorTopicName>/camera_l515/color/image_raw</colorTopicName>
      <colorCameraInfoTopicName>/camera_l515/color/camera_info</colorCameraInfoTopicName>
      <infraredTopicName>/camera_l515/infra/image_raw</infraredTopicName>
      <infraredCameraInfoTopicName>/camera_l515/infra/camera_info</infraredCameraInfoTopicName>
      <colorOpticalframeName>camera_l515_color_optical_frame</colorOpticalframeName>
      <depthOpticalframeName>camera_l515_depth_optical_frame</depthOpticalframeName>
      <infraredOpticalframeName>camera_l515_infra_optical_frame</infraredOpticalframeName>
      <rangeMinDepth>0.2</rangeMinDepth>
      <rangeMaxDepth>10.0</rangeMaxDepth>
      <pointCloud>False</pointCloud>
      <pointCloudTopicName>/camera_l515/depth/color/points</pointCloudTopicName>
      <pointCloudCutoff>0.25</pointCloudCutoff>
      <pointCloudCutoffMax>9.0</pointCloudCutoffMax>
    </plugin>
  </gazebo>
  <joint name="camera_t265_odom_frame_joint" type="fixed">
    <origin xyz="0.35 0.06 0.86" rpy="0.0 0.0 0.0"/>
    <parent link="base_link_mb"/>
    <child link="camera_t265_odom_frame"/>
  </joint>
  <joint name="camera_t265_pose_frame_joint" type="fixed">
    <origin xyz="0.0 0.0 0.0" rpy="0.0 0.0 0.0"/>
    <parent link="camera_t265_odom_frame"/>
    <child link="camera_t265_pose_frame"/>
  </joint>
  <link name="camera_t265_odom_frame"/>
  <link name="camera_t265_pose_frame">
    <inertial>
      <origin xyz="0.0 0.0 0.0" rpy="0.0 0.0 0.0"/>
      <mass value="0.055"/>
      <inertia ixx="9.108e-05" ixy="0.0" ixz="0.0" iyy="2.51e-06" iyz="0.0" izz="8.931e-05"/>
    </inertial>
    <visual>
      <origin xyz="0.0 0.0 0.0" rpy="1.57 0.0 1.57"/>
      <geometry>
        <mesh filename="package://realsense_ros_gazebo/meshes/realsense_t265.stl" scale="0.001 0.001 0.001"/>
      </geometry>
    </visual>
    <collision>
      <geometry>
        <box size="0.013 0.108 0.024"/>
      </geometry>
    </collision>
  </link>
  <joint name="camera_t265_joint" type="fixed">
    <origin xyz="0.0 0.0 0.0" rpy="0.0 0.0 0.0"/>
    <parent link="camera_t265_pose_frame"/>
    <child link="camera_t265_link"/>
  </joint>
  <link name="camera_t265_link"/>
  <joint name="camera_t265_fisheye1_joint" type="fixed">
    <origin xyz="0.0 0.042 0.0" rpy="0.0 0.0 0.0"/>
    <parent link="camera_t265_link"/>
    <child link="camera_t265_fisheye1_frame"/>
  </joint>
  <link name="camera_t265_fisheye1_frame"/>
  <joint name="camera_t265_fisheye1_optical_joint" type="fixed">
    <origin xyz="0.01 0.0 0.0" rpy="0.0 0.0 0.0"/>
    <parent link="camera_t265_fisheye1_frame"/>
    <child link="camera_t265_fisheye1_optical_frame"/>
  </joint>
  <link name="camera_t265_fisheye1_optical_frame"/>
  <gazebo reference="camera_t265_fisheye1_optical_frame">
    <sensor name="camera" type="wideanglecamera">
      <camera>
        <horizontal_fov>6.283</horizontal_fov>
        <image>
          <width>800</width>
          <height>848</height>
        </image>
        <clip>
          <near>0.1</near>
          <far>100</far>
        </clip>
        <lens>
          <type>custom</type>
          <custom_function>
            <c1>1.05</c1>
            <c2>4</c2>
            <f>1.0</f>
            <fun>tan</fun>
          </custom_function>
          <scale_to_hfov>true</scale_to_hfov>
          <cutoff_angle>3.1415</cutoff_angle>
          <env_texture_size>512</env_texture_size>
        </lens>
        <always_on>true</always_on>
        <update_rate>30</update_rate>
      </camera>
      <plugin filename="libgazebo_ros_camera.so" name="camera_controller">
        <alwaysOn>true</alwaysOn>
        <updateRate>30.0</updateRate>
        <cameraName>camera_t265/fisheye1</cameraName>
        <imageTopicName>image_raw</imageTopicName>
        <cameraInfoTopicName>camera_info</cameraInfoTopicName>
        <frameName>camera_t265_fisheye1_optical_frame</frameName>
        <hackBaseline>0.07</hackBaseline>
        <distortionK1>-0.007419134024530649</distortionK1>
        <distortionK2>0.041209351271390915</distortionK2>
        <distortionK3>-0.03811917081475258</distortionK3>
        <distortionT1>0.006366158835589886</distortionT1>
        <distortionT2>0.0</distortionT2>
        <CxPrime>416.00531005859375</CxPrime>
        <Cx>16.00531005859375</Cx>
        <Cy>403.38909912109375</Cy>
      </plugin>
    </sensor>
  </gazebo>
  <joint name="camera_t265_fisheye2_joint" type="fixed">
    <origin xyz="0.0 -0.022 0.0" rpy="0.0 0.0 0.0"/>
    <parent link="camera_t265_link"/>
    <child link="camera_t265_fisheye2_frame"/>
  </joint>
  <link name="camera_t265_fisheye2_frame"/>
  <joint name="camera_t265_fisheye2_optical_joint" type="fixed">
    <origin xyz="0.01 0.0 0.0" rpy="0.0 0.0 0.0"/>
    <parent link="camera_t265_fisheye2_frame"/>
    <child link="camera_t265_fisheye2_optical_frame"/>
  </joint>
  <link name="camera_t265_fisheye2_optical_frame"/>
  <gazebo reference="camera_t265_fisheye2_optical_frame">
    <sensor name="camera" type="wideanglecamera">
      <camera>
        <horizontal_fov>6.283</horizontal_fov>
        <image>
          <width>800</width>
          <height>848</height>
        </image>
        <clip>
          <near>0.1</near>
          <far>100</far>
        </clip>
        <lens>
          <type>custom</type>
          <custom_function>
            <c1>1.05</c1>
            <c2>4</c2>
            <f>1.0</f>
            <fun>tan</fun>
          </custom_function>
          <scale_to_hfov>true</scale_to_hfov>
          <cutoff_angle>3.1415</cutoff_angle>
          <env_texture_size>512</env_texture_size>
        </lens>
        <always_on>true</always_on>
        <update_rate>30</update_rate>
      </camera>
      <plugin filename="libgazebo_ros_camera.so" name="camera_controller">
        <alwaysOn>true</alwaysOn>
        <updateRate>30.0</updateRate>
        <cameraName>camera_t265/fisheye2</cameraName>
        <imageTopicName>image_raw</imageTopicName>
        <cameraInfoTopicName>camera_info</cameraInfoTopicName>
        <frameName>camera_t265_fisheye2_optical_frame</frameName>
        <hackBaseline>0.07</hackBaseline>
        <distortionK1>-0.007419134024530649</distortionK1>
        <distortionK2>0.041209351271390915</distortionK2>
        <distortionK3>-0.03811917081475258</distortionK3>
        <distortionT1>0.006366158835589886</distortionT1>
        <distortionT2>0.0</distortionT2>
        <CxPrime>416.00531005859375</CxPrime>
        <Cx>16.00531005859375</Cx>
        <Cy>403.38909912109375</Cy>
      </plugin>
    </sensor>
  </gazebo>
  <joint name="camera_t265_gyro_joint" type="fixed">
    <origin xyz="0.0 0.0 0.0" rpy="0.0 0.0 0.0"/>
    <parent link="camera_t265_link"/>
    <child link="camera_t265_gyro_frame"/>
  </joint>
  <link name="camera_t265_gyro_frame"/>
  <gazebo reference="camera_t265_gyro_frame">
    <gravity>true</gravity>
    <sensor name="camera_t265_imu" type="imu">
      <always_on>true</always_on>
      <update_rate>30.0</update_rate>
      <visualize>false</visualize>
      <plugin filename="libgazebo_ros_imu_sensor.so" name="imu_plugin">
        <topicName>camera_t265/gyro/sample</topicName>
        <bodyName>camera_t265_pose_frame</bodyName>
        <updateRateHZ>30.0</updateRateHZ>
        <gaussianNoise>0.000001</gaussianNoise>
        <xyzOffset>0 0 0</xyzOffset>
        <rpyOffset>0 0 0</rpyOffset>
        <frameName>camera_t265_link</frameName>
      </plugin>
    </sensor>
  </gazebo>
  <joint name="camera_t265_accel_joint" type="fixed">
    <origin xyz="0.0 0.0 0.0" rpy="0.0 0.0 0.0"/>
    <parent link="camera_t265_link"/>
    <child link="camera_t265_accel_frame"/>
  </joint>
  <link name="camera_t265_accel_frame"/>
  <gazebo>
    <plugin filename="libgazebo_ros_p3d.so" name="p3d_base_controller">
      <alwaysOn>true</alwaysOn>
      <updateRate>30.0</updateRate>
      <bodyName>camera_t265_odom_frame</bodyName>
      <topicName>camera_t265/odom/sample</topicName>
      <gaussianNoise>0.001</gaussianNoise>
      <frameName>world</frameName>
      <xyzOffsets>0 0 0</xyzOffsets>
      <rpyOffsets>0 0 0</rpyOffsets>
    </plugin>
  </gazebo>
  <link name="base_footprint"/>
  <joint name="base_joint" type="fixed">
    <origin xyz="0.0 0.0 0.01" rpy="0.0 0.0 0.0"/>
    <parent link="base_footprint"/>
    <child link="base_link_mb"/>
  </joint>
  <link name="base_link_mb">
    <visual>
      <origin xyz="-0.43 -0.33 0.03" rpy="1.57 0.0 1.57"/>
      <geometry>
        <mesh filename="package://zau2_description/meshes/moving_base/moving_base.STL" scale="0.001 0.001 0.001"/>
      </geometry>
      <material name="light_black"/>
    </visual>
    <collision>
      <origin xyz="0.0 0.0 0.459" rpy="0.0 0.0 0.0"/>
      <geometry>
        <box size="0.9 0.6 0.77"/>
      </geometry>
    </collision>
  </link>
  <link name="inertial_link">
    <inertial>
      <origin xyz="-0.00065 -0.085 0.062" rpy="0 0 0"/>
      <mass value="500.0"/>
      <inertia ixx="0.6022" ixy="-0.02364" ixz="-0.1197" iyy="1.7386" iyz="-0.001544" izz="2.0296"/>
    </inertial>
  </link>
  <joint name="inertial_joint" type="fixed">
    <origin xyz="0.0 0.0 0.0" rpy="0.0 0.0 0.0"/>
    <parent link="base_link_mb"/>
    <child link="inertial_link"/>
  </joint>
  <joint name="wheel_left_joint" type="continuous">
    <origin xyz="0.0 0.325 0.074" rpy="-1.57 0.0 0.0"/>
    <axis xyz="0.0 0.0 1.0"/>
    <parent link="base_link_mb"/>
    <child link="wheel_left_link"/>
  </joint>
  <link name="wheel_left_link">
    <inertial>
      <origin xyz="0.0 0.0 0.0" rpy="0 0 0"/>
      <mass value="2.637"/>
      <inertia ixx="0.02467" ixy="0.0" ixz="0.0" iyy="0.04411" iyz="0.0" izz="0.02467"/>
    </inertial>
    <visual>
      <origin xyz="0.0 0.0 -0.055" rpy="-1.57 0.0 0.0"/>
      <geometry>
        <mesh filename="package://zau2_description/meshes/wheels/left_tire.stl" scale="0.0025 0.0025 0.0025"/>
      </geometry>
      <material name="dark"/>
    </visual>
    <collision>
      <origin xyz="0.0 0.0 0.0" rpy="0.0 0.0 0.0"/>
      <geometry>
        <cylinder radius="0.084" length="0.044"/>
      </geometry>
    </collision>
  </link>
  <joint name="wheel_right_joint" type="continuous">
    <origin xyz="0.0 -0.325 0.074" rpy="-1.57 0.0 0.0"/>
    <axis xyz="0.0 0.0 1.0"/>
    <parent link="base_link_mb"/>
    <child link="wheel_right_link"/>
  </joint>
  <link name="wheel_right_link">
    <inertial>
      <origin xyz="0.0 0.0 0.0" rpy="0 0 0"/>
      <mass value="2.637"/>
      <inertia ixx="0.02467" ixy="0.0" ixz="0.0" iyy="0.04411" iyz="0.0" izz="0.02467"/>
    </inertial>
    <visual>
      <origin xyz="0.0 0.0 0.055" rpy="1.57 0.0 0.0"/>
      <geometry>
        <mesh filename="package://zau2_description/meshes/wheels/left_tire.stl" scale="0.0025 0.0025 0.0025"/>
      </geometry>
      <material name="dark"/>
    </visual>
    <collision>
      <origin xyz="0.0 0.0 0.0" rpy="0.0 0.0 0.0"/>
      <geometry>
        <cylinder radius="0.084" length="0.044"/>
      </geometry>
    </collision>
  </link>
  <joint name="caster_back_right_joint" type="fixed">
    <origin xyz="-0.345 -0.19 -0.004" rpy="-1.57 0.0 0.0"/>
    <parent link="base_link_mb"/>
    <child link="caster_back_right_link"/>
  </joint>
  <link name="caster_back_right_link">
    <inertial>
      <origin xyz="0.0 0.0 0.0" rpy="0 0 0"/>
      <mass value="0.005"/>
      <inertia ixx="0.001" ixy="0.0" ixz="0.0" iyy="0.001" iyz="0.0" izz="0.001"/>
    </inertial>
    <visual>
      <origin xyz="0.027 -0.06 0.0" rpy="1.57 0.0 0.0"/>
      <geometry>
        <mesh filename="package://zau2_description/meshes/wheels/left_tire.stl" scale="0.002 0.002 0.002"/>
      </geometry>
      <material name="dark"/>
    </visual>
    <collision>
      <origin xyz="0.0 0.001 0.0" rpy="0.0 0.0 0.0"/>
      <geometry>
        <box size="0.03 0.009 0.078"/>
      </geometry>
    </collision>
  </link>
  <joint name="caster_back_left_joint" type="fixed">
    <origin xyz="-0.345 0.19 -0.004" rpy="-1.57 0.0 0.0"/>
    <parent link="base_link_mb"/>
    <child link="caster_back_left_link"/>
  </joint>
  <link name="caster_back_left_link">
    <inertial>
      <origin xyz="0.0 0.0 0.0" rpy="0 0 0"/>
      <mass value="0.005"/>
      <inertia ixx="0.001" ixy="0.0" ixz="0.0" iyy="0.001" iyz="0.0" izz="0.001"/>
    </inertial>
    <visual>
      <origin xyz="0.027 -0.06 0.0" rpy="-1.57 0.0 0.0"/>
      <geometry>
        <mesh filename="package://zau2_description/meshes/wheels/left_tire.stl" scale="0.002 0.002 0.002"/>
      </geometry>
      <material name="dark"/>
    </visual>
    <collision>
      <origin xyz="0.0 0.001 0.0" rpy="0.0 0.0 0.0"/>
      <geometry>
        <box size="0.03 0.009 0.078"/>
      </geometry>
    </collision>
  </link>
  <joint name="caster_front_right_joint" type="fixed">
    <origin xyz="0.345 -0.19 -0.004" rpy="-1.57 0.0 0.0"/>
    <parent link="base_link_mb"/>
    <child link="caster_front_right_link"/>
  </joint>
  <link name="caster_front_right_link">
    <inertial>
      <origin xyz="0.0 0.0 0.0" rpy="0 0 0"/>
      <mass value="0.005"/>
      <inertia ixx="0.001" ixy="0.0" ixz="0.0" iyy="0.001" iyz="0.0" izz="0.001"/>
    </inertial>
    <visual>
      <origin xyz="0.0 -0.06 0.0" rpy="1.57 0.0 0.0"/>
      <geometry>
        <mesh filename="package://zau2_description/meshes/wheels/left_tire.stl" scale="0.002 0.002 0.002"/>
      </geometry>
      <material name="dark"/>
    </visual>
    <collision>
      <origin xyz="0.0 0.001 0.0" rpy="0.0 0.0 0.0"/>
      <geometry>
        <box size="0.03 0.009 0.078"/>
      </geometry>
    </collision>
  </link>
  <joint name="caster_front_left_joint" type="fixed">
    <origin xyz="0.345 0.19 -0.004" rpy="-1.57 0.0 0.0"/>
    <parent link="base_link_mb"/>
    <child link="caster_front_left_link"/>
  </joint>
  <link name="caster_front_left_link">
    <inertial>
      <origin xyz="0.0 0.0 0.0" rpy="0 0 0"/>
      <mass value="0.005"/>
      <inertia ixx="0.001" ixy="0.0" ixz="0.0" iyy="0.001" iyz="0.0" izz="0.001"/>
    </inertial>
    <visual>
      <origin xyz="0.0 -0.06 0.0" rpy="-1.57 0.0 0.0"/>
      <geometry>
        <mesh filename="package://zau2_description/meshes/wheels/left_tire.stl" scale="0.002 0.002 0.002"/>
      </geometry>
      <material name="dark"/>
    </visual>
    <collision>
      <origin xyz="0.0 0.001 0.0" rpy="0.0 0.0 0.0"/>
      <geometry>
        <box size="0.03 0.009 0.078"/>
      </geometry>
    </collision>
  </link>
  <joint name="imu_joint" type="fixed">
    <origin xyz="0.0 0.0 0.068" rpy="0.0 0.0 0.0"/>
    <parent link="base_link_mb"/>
    <child link="imu_link"/>
  </joint>
  <link name="imu_link"/>
  <joint name="scan_joint_front" type="fixed">
    <origin xyz="-0.45 0.3 0.18" rpy="0.0 0.0 0.0"/>
    <parent link="base_link_mb"/>
    <child link="base_scan_front"/>
  </joint>
  <link name="base_scan_front">
    <inertial>
      <origin xyz="0.0 0.0 0.0" rpy="0 0 0"/>
      <mass value="0.114"/>
      <inertia ixx="0.001" ixy="0.0" ixz="0.0" iyy="0.001" iyz="0.0" izz="0.001"/>
    </inertial>
    <collision>
      <origin xyz="0.015 0.0 -0.0065" rpy="0.0 0.0 0.0"/>
      <geometry>
        <cylinder radius="0.055" length="0.0315"/>
      </geometry>
    </collision>
  </link>
  <joint name="scan_joint_back" type="fixed">
    <origin xyz="0.5 -0.3 0.18" rpy="0.0 0.0 -3.14"/>
    <parent link="base_link_mb"/>
    <child link="base_scan_back"/>
  </joint>
  <link name="base_scan_back">
    <inertial>
      <origin xyz="0.0 0.0 0.0" rpy="0 0 0"/>
      <mass value="0.114"/>
      <inertia ixx="0.001" ixy="0.0" ixz="0.0" iyy="0.001" iyz="0.0" izz="0.001"/>
    </inertial>
    <collision>
      <origin xyz="0.015 0.0 -0.0065" rpy="0.0 0.0 0.0"/>
      <geometry>
        <cylinder radius="0.055" length="0.0315"/>
      </geometry>
    </collision>
  </link>
  <transmission name="shoulder_pan_trans">
    <type>transmission_interface/SimpleTransmission</type>
    <joint name="shoulder_pan_joint">
      <hardwareInterface>hardware_interface/PositionJointInterface</hardwareInterface>
    </joint>
    <actuator name="shoulder_pan_motor">
      <mechanicalReduction>1.0</mechanicalReduction>
    </actuator>
  </transmission>
  <transmission name="shoulder_lift_trans">
    <type>transmission_interface/SimpleTransmission</type>
    <joint name="shoulder_lift_joint">
      <hardwareInterface>hardware_interface/PositionJointInterface</hardwareInterface>
    </joint>
    <actuator name="shoulder_lift_motor">
      <mechanicalReduction>1.0</mechanicalReduction>
    </actuator>
  </transmission>
  <transmission name="elbow_trans">
    <type>transmission_interface/SimpleTransmission</type>
    <joint name="elbow_joint">
      <hardwareInterface>hardware_interface/PositionJointInterface</hardwareInterface>
    </joint>
    <actuator name="elbow_motor">
      <mechanicalReduction>1.0</mechanicalReduction>
    </actuator>
  </transmission>
  <transmission name="wrist_1_trans">
    <type>transmission_interface/SimpleTransmission</type>
    <joint name="wrist_1_joint">
      <hardwareInterface>hardware_interface/PositionJointInterface</hardwareInterface>
    </joint>
    <actuator name="wrist_1_motor">
      <mechanicalReduction>1.0</mechanicalReduction>
    </actuator>
  </transmission>
  <transmission name="wrist_2_trans">
    <type>transmission_interface/SimpleTransmission</type>
    <joint name="wrist_2_joint">
      <hardwareInterface>hardware_interface/PositionJointInterface</hardwareInterface>
    </joint>
    <actuator name="wrist_2_motor">
      <mechanicalReduction>1.0</mechanicalReduction>
    </actuator>
  </transmission>
  <transmission name="wrist_3_trans">
    <type>transmission_interface/SimpleTransmission</type>
    <joint name="wrist_3_joint">
      <hardwareInterface>hardware_interface/PositionJointInterface</hardwareInterface>
    </joint>
    <actuator name="wrist_3_motor">
      <mechanicalReduction>1.0</mechanicalReduction>
    </actuator>
  </transmission>
  <link name="base_link"/>
  <link name="base_link_inertia">
    <inertial>
      <origin xyz="0.0 0.0 0.0" rpy="0.0 0.0 0.0"/>
      <mass value="4.0"/>
      <inertia ixx="0.0061063308908" ixy="0.0" ixz="0.0" iyy="0.0061063308908" iyz="0.0" izz="0.01125"/>
    </inertial>
    <visual>
      <origin xyz="0.0 0.0 0.0" rpy="0.0 0.0 3.141592653589793"/>
      <geometry>
        <mesh filename="package://ur_description/meshes/ur10e/visual/base.dae"/>
      </geometry>
      <material name="LightGrey">
        <color rgba="0.7 0.7 0.7 1.0"/>
      </material>
    </visual>
    <collision>
      <origin xyz="0.0 0.0 0.0" rpy="0.0 0.0 3.141592653589793"/>
      <geometry>
        <mesh filename="package://ur_description/meshes/ur10e/collision/base.stl"/>
      </geometry>
    </collision>
  </link>
  <link name="shoulder_link">
    <inertial>
      <origin xyz="0.0 0.0 0.0" rpy="0.0 0.0 0.0"/>
      <mass value="7.778"/>
      <inertia ixx="0.03147431257693659" ixy="0.0" ixz="0.0" iyy="0.03147431257693659" iyz="0.0" izz="0.021875624999999996"/>
    </inertial>
    <visual>
      <origin xyz="0.0 0.0 0.0" rpy="0.0 0.0 3.141592653589793"/>
      <geometry>
        <mesh filename="package://ur_description/meshes/ur10e/visual/shoulder.dae"/>
      </geometry>
      <material name="LightGrey">
        <color rgba="0.7 0.7 0.7 1.0"/>
      </material>
    </visual>
    <collision>
      <origin xyz="0.0 0.0 0.0" rpy="0.0 0.0 3.141592653589793"/>
      <geometry>
        <mesh filename="package://ur_description/meshes/ur10e/collision/shoulder.stl"/>
      </geometry>
    </collision>
  </link>
  <link name="upper_arm_link">
    <inertial>
      <origin xyz="-0.306 0.0 0.175" rpy="0.0 1.5707963267948966 0.0"/>
      <mass value="12.93"/>
      <inertia ixx="0.42175380379841093" ixy="0.0" ixz="0.0" iyy="0.42175380379841093" iyz="0.0" izz="0.03636562499999999"/>
    </inertial>
    <visual>
      <origin xyz="0.0 0.0 0.1762" rpy="1.5707963267948966 0.0 -1.5707963267948966"/>
      <geometry>
        <mesh filename="package://ur_description/meshes/ur10e/visual/upperarm.dae"/>
      </geometry>
      <material name="LightGrey">
        <color rgba="0.7 0.7 0.7 1.0"/>
      </material>
    </visual>
    <collision>
      <origin xyz="0.0 0.0 0.1762" rpy="1.5707963267948966 0.0 -1.5707963267948966"/>
      <geometry>
        <mesh filename="package://ur_description/meshes/ur10e/collision/upperarm.stl"/>
      </geometry>
    </collision>
  </link>
  <link name="forearm_link">
    <inertial>
      <origin xyz="-0.285775 0.0 0.0393" rpy="0.0 1.5707963267948966 0.0"/>
      <mass value="3.87"/>
      <inertia ixx="0.11079302548902206" ixy="0.0" ixz="0.0" iyy="0.11079302548902206" iyz="0.0" izz="0.010884375"/>
    </inertial>
    <visual>
      <origin xyz="0.0 0.0 0.0393" rpy="1.5707963267948966 0.0 -1.5707963267948966"/>
      <geometry>
        <mesh filename="package://ur_description/meshes/ur10e/visual/forearm.dae"/>
      </geometry>
      <material name="LightGrey">
        <color rgba="0.7 0.7 0.7 1.0"/>
      </material>
    </visual>
    <collision>
      <origin xyz="0.0 0.0 0.0393" rpy="1.5707963267948966 0.0 -1.5707963267948966"/>
      <geometry>
        <mesh filename="package://ur_description/meshes/ur10e/collision/forearm.stl"/>
      </geometry>
    </collision>
  </link>
  <link name="wrist_1_link">
    <inertial>
      <origin xyz="0.0 0.0 0.0" rpy="0.0 0.0 0.0"/>
      <mass value="1.96"/>
      <inertia ixx="0.005108247956699999" ixy="0.0" ixz="0.0" iyy="0.005108247956699999" iyz="0.0" izz="0.005512499999999999"/>
    </inertial>
    <visual>
      <origin xyz="0.0 0.0 -0.135" rpy="1.5707963267948966 0.0 0.0"/>
      <geometry>
        <mesh filename="package://ur_description/meshes/ur10e/visual/wrist1.dae"/>
      </geometry>
      <material name="LightGrey">
        <color rgba="0.7 0.7 0.7 1.0"/>
      </material>
    </visual>
    <collision>
      <origin xyz="0.0 0.0 -0.135" rpy="1.5707963267948966 0.0 0.0"/>
      <geometry>
        <mesh filename="package://ur_description/meshes/ur10e/collision/wrist1.stl"/>
      </geometry>
    </collision>
  </link>
  <link name="wrist_2_link">
    <inertial>
      <origin xyz="0.0 0.0 0.0" rpy="0.0 0.0 0.0"/>
      <mass value="1.96"/>
      <inertia ixx="0.005108247956699999" ixy="0.0" ixz="0.0" iyy="0.005108247956699999" iyz="0.0" izz="0.005512499999999999"/>
    </inertial>
    <visual>
      <origin xyz="0.0 0.0 -0.12" rpy="0.0 0.0 0.0"/>
      <geometry>
        <mesh filename="package://ur_description/meshes/ur10e/visual/wrist2.dae"/>
      </geometry>
      <material name="LightGrey">
        <color rgba="0.7 0.7 0.7 1.0"/>
      </material>
    </visual>
    <collision>
      <origin xyz="0.0 0.0 -0.12" rpy="0.0 0.0 0.0"/>
      <geometry>
        <mesh filename="package://ur_description/meshes/ur10e/collision/wrist2.stl"/>
      </geometry>
    </collision>
  </link>
  <link name="wrist_3_link">
    <inertial>
      <origin xyz="0.0 0.0 -0.025" rpy="0.0 0.0 0.0"/>
      <mass value="0.202"/>
      <inertia ixx="0.00014434577559500002" ixy="0.0" ixz="0.0" iyy="0.00014434577559500002" iyz="0.0" izz="0.00020452500000000002"/>
    </inertial>
    <visual>
      <origin xyz="0.0 0.0 -0.1168" rpy="1.5707963267948966 0.0 0.0"/>
      <geometry>
        <mesh filename="package://ur_description/meshes/ur10e/visual/wrist3.dae"/>
      </geometry>
      <material name="LightGrey">
        <color rgba="0.7 0.7 0.7 1.0"/>
      </material>
    </visual>
    <collision>
      <origin xyz="0.0 0.0 -0.1168" rpy="1.5707963267948966 0.0 0.0"/>
      <geometry>
        <mesh filename="package://ur_description/meshes/ur10e/collision/wrist3.stl"/>
      </geometry>
    </collision>
  </link>
  <joint name="base_link-base_link_inertia" type="fixed">
    <origin xyz="0.0 0.0 0.0" rpy="0.0 0.0 3.141592653589793"/>
    <parent link="base_link"/>
    <child link="base_link_inertia"/>
  </joint>
  <joint name="shoulder_pan_joint" type="revolute">
    <origin xyz="0.0 0.0 0.1807" rpy="0.0 0.0 0.0"/>
    <axis xyz="0.0 0.0 1.0"/>
    <parent link="base_link_inertia"/>
    <child link="shoulder_link"/>
    <limit effort="330.0" lower="-3.141592653589793" upper="3.141592653589793" velocity="2.0943951023931953"/>
    <dynamics damping="0.0" friction="0.0"/>
  </joint>
  <joint name="shoulder_lift_joint" type="revolute">
    <origin xyz="0.0 0.0 0.0" rpy="1.570796327 0.0 0.0"/>
    <axis xyz="0.0 0.0 1.0"/>
    <parent link="shoulder_link"/>
    <child link="upper_arm_link"/>
    <limit effort="330.0" lower="-1.8325957145940461" upper="0.0" velocity="2.0943951023931953"/>
    <dynamics damping="0.0" friction="0.0"/>
  </joint>
  <joint name="elbow_joint" type="revolute">
    <origin xyz="-0.6127 0.0 0.0" rpy="0.0 0.0 0.0"/>
    <axis xyz="0.0 0.0 1.0"/>
    <parent link="upper_arm_link"/>
    <child link="forearm_link"/>
    <limit effort="150.0" lower="-3.141592653589793" upper="3.141592653589793" velocity="3.141592653589793"/>
    <dynamics damping="0.0" friction="0.0"/>
  </joint>
  <joint name="wrist_1_joint" type="revolute">
    <origin xyz="-0.57155 0.0 0.17415" rpy="0.0 0.0 0.0"/>
    <axis xyz="0.0 0.0 1.0"/>
    <parent link="forearm_link"/>
    <child link="wrist_1_link"/>
    <limit effort="56.0" lower="-6.283185307179586" upper="6.283185307179586" velocity="3.141592653589793"/>
    <dynamics damping="0.0" friction="0.0"/>
  </joint>
  <joint name="wrist_2_joint" type="revolute">
    <origin xyz="0.0 -0.11985 -2.458164590756244e-11" rpy="1.570796327 0.0 0.0"/>
    <axis xyz="0.0 0.0 1.0"/>
    <parent link="wrist_1_link"/>
    <child link="wrist_2_link"/>
    <limit effort="56.0" lower="-6.283185307179586" upper="6.283185307179586" velocity="3.141592653589793"/>
    <dynamics damping="0.0" friction="0.0"/>
  </joint>
  <joint name="wrist_3_joint" type="revolute">
    <origin xyz="0.0 0.11655 -2.390480459346185e-11" rpy="1.570796326589793 3.141592653589793 3.141592653589793"/>
    <axis xyz="0.0 0.0 1.0"/>
    <parent link="wrist_2_link"/>
    <child link="wrist_3_link"/>
    <limit effort="56.0" lower="-6.283185307179586" upper="6.283185307179586" velocity="3.141592653589793"/>
    <dynamics damping="0.0" friction="0.0"/>
  </joint>
  <link name="base"/>
  <joint name="base_link-base_fixed_joint" type="fixed">
    <origin xyz="0.0 0.0 0.0" rpy="0.0 0.0 3.141592653589793"/>
    <parent link="base_link"/>
    <child link="base"/>
  </joint>
  <link name="flange"/>
  <joint name="wrist_3-flange" type="fixed">
    <origin xyz="0.0 0.0 0.0" rpy="0.0 -1.5707963267948966 -1.5707963267948966"/>
    <parent link="wrist_3_link"/>
    <child link="flange"/>
  </joint>
  <link name="tool0"/>
  <joint name="flange-tool0" type="fixed">
    <origin xyz="0.0 0.0 0.0" rpy="1.5707963267948966 0.0 1.5707963267948966"/>
    <parent link="flange"/>
    <child link="tool0"/>
  </joint>
  <gazebo reference="shoulder_link">
    <selfCollide>true</selfCollide>
  </gazebo>
  <gazebo reference="upper_arm_link">
    <selfCollide>true</selfCollide>
  </gazebo>
  <gazebo reference="forearm_link">
    <selfCollide>true</selfCollide>
  </gazebo>
  <gazebo reference="wrist_1_link">
    <selfCollide>true</selfCollide>
  </gazebo>
  <gazebo reference="wrist_3_link">
    <selfCollide>true</selfCollide>
  </gazebo>
  <gazebo reference="wrist_2_link">
    <selfCollide>true</selfCollide>
  </gazebo>
  <gazebo reference="ee_link">
    <selfCollide>true</selfCollide>
  </gazebo>
  <gazebo>
    <plugin filename="libgazebo_ros_control.so" name="ros_control">
    </plugin>
  </gazebo>
  <joint name="moving_base_to_ur10e" type="fixed">
    <origin xyz="-0.31535278648851883 -0.15689707283949922 1.0132105173631252" rpy="-0.03225828676345766 0.0020807976157978894 0.004851933439777321"/>
    <parent link="base_link_mb"/>
    <child link="base_link"/>
  </joint>
  <joint name="hand_camera_joint" type="fixed">
    <origin xyz="-0.02 0.05 0.07" rpy="0.0 0.0 0.0"/>
    <parent link="flange"/>
    <child link="hand_camera_link"/>
  </joint>
  <link name="hand_camera_link">
    <inertial>
      <origin xyz="0.0 0.0 0.0" rpy="0 0 0"/>
      <mass value="0.564"/>
      <inertia ixx="0.003881243" ixy="0.0" ixz="0.0" iyy="0.00049894" iyz="0.0" izz="0.003879257"/>
    </inertial>
    <collision>
      <origin xyz="-0.01 -0.06 0.0" rpy="0.0 0.0 0.0"/>
      <geometry>
        <box size="0.04 0.165 0.03"/>
      </geometry>
    </collision>
  </link>
  <gazebo reference="hand_camera_link">
    <selfCollide>false</selfCollide>
  </gazebo>
  <joint name="hand_camera_rgb_joint" type="fixed">
    <origin xyz="-0.012558657718883677 -0.033413699142940984 0.16563534939530006" rpy="-0.033482883854487056 -0.010845528509673144 0.0011380645432759427"/>
    <parent link="hand_camera_link"/>
    <child link="hand_camera_rgb_frame"/>
  </joint>
  <link name="hand_camera_rgb_frame"/>
  <joint name="hand_camera_rgb_optical_joint" type="fixed">
    <origin xyz="0.0 0.0 0.0" rpy="-1.5707963267948966 0.0 -1.5707963267948966"/>
    <parent link="hand_camera_rgb_frame"/>
    <child link="hand_camera_rgb_optical_frame"/>
  </joint>
  <link name="hand_camera_rgb_optical_frame">
    <visual>
      <origin xyz="0.0 0.0 -0.03" rpy="1.5707963267948966 0.0 0.0"/>
      <geometry>
        <mesh filename="package://zau2_description/meshes/sensors/astra2.dae" scale="1.0 1.0 1.0"/>
      </geometry>
    </visual>
  </link>
  <joint name="hand_camera_depth_joint" type="fixed">
    <origin xyz="0.0 -0.02 0.0" rpy="0.0 0.0 0.0"/>
    <parent link="hand_camera_link"/>
    <child link="hand_camera_depth_frame"/>
  </joint>
  <link name="hand_camera_depth_frame"/>
  <joint name="hand_camera_depth_optical_joint" type="fixed">
    <origin xyz="0.0 0.0 0.0" rpy="-1.5707963267948966 0.0 -1.5707963267948966"/>
    <parent link="hand_camera_depth_frame"/>
    <child link="hand_camera_depth_optical_frame"/>
  </joint>
  <link name="hand_camera_depth_optical_frame"/>
  <gazebo reference="hand_camera_depth_frame">
    <sensor name="camera" type="depth">
      <always_on>true</always_on>
      <update_rate>20.0</update_rate>
      <camera>
        <horizontal_fov>1.0471975511965976</horizontal_fov>
        <image>
          <format>B8G8R8</format>
          <width>640</width>
          <height>480</height>
        </image>
        <clip>
          <near>0.10</near>
          <far>8.0</far>
        </clip>
      </camera>
      <plugin filename="libgazebo_ros_openni_kinect.so" name="hand_camera_camera_controller">
        <cameraName>hand_camera</cameraName>
        <alwaysOn>true</alwaysOn>
        <updateRate>10</updateRate>
        <imageTopicName>rgb/image_raw</imageTopicName>
        <depthImageTopicName>depth/image_raw</depthImageTopicName>
        <pointCloudTopicName>depth/points</pointCloudTopicName>
        <cameraInfoTopicName>rgb/camera_info</cameraInfoTopicName>
        <depthImageCameraInfoTopicName>depth/camera_info</depthImageCameraInfoTopicName>
        <frameName>hand_camera_depth_optical_frame</frameName>
        <baseline>0.1</baseline>
        <distortion_k1>0.0</distortion_k1>
        <distortion_k2>0.0</distortion_k2>
        <distortion_k3>0.0</distortion_k3>
        <distortion_t1>0.0</distortion_t1>
        <distortion_t2>0.0</distortion_t2>
        <pointCloudCutoff>0.4</pointCloudCutoff>
      </plugin>
    </sensor>
  </gazebo>
</robot>